Workbook

Sheet Pricing Data
A1: Security ID | B1: Security Name | C1: Asset Class | D1: Currency | E1: Prior Price ($) | F1: Current Price ($) | G1: Vendor Price ($) | H1: Price Age (Days) | I1: Volume | J1: Market Value ($mm) | K1: daily change% | L1: vendor difference% | M1: exceptions statuts | N1: PRIORITY
A2: SEC00001 | B2: Harbor Holdings 1 | C2: Government Bond | D2: USD | E2: 88.7515 | F2: 89.0429 | G2: 89.4729 | H2: 0 | I2: 1835068 | J2: 209.55 | K2: =(PricingDataTable[[#This Row],[Current Price ($)]]-PricingDataTable[[#This Row],[Prior Price ($)]])/PricingDataTable[[#This Row],[Prior Price ($)]] -> 0.0032833248 | L2: =(PricingDataTable[[#This Row],[Vendor Price ($)]]-PricingDataTable[[#This Row],[Current Price ($)]])/PricingDataTable[[#This Row],[Current Price ($)]] -> 0.0048291329 | M2: =IF(OR(F2="",F2=0),"MISSING",IF(H2>=3,"STALE",IF(ABS(K2)>=5%,"LARGE MOVE",IF(ABS(L2)>=2%,"VENDOR DIFFERENCE","PASS")))) -> PASS | N2: =IF(M2="PASS","NONE",IF(M2="MISSING","HIGH",IF(OR(ABS(K2)>=10%,ABS(L2)>=5%),"HIGH",IF(OR(ABS(K2)>=7%,ABS(L2)>=3%,H2>=5),"MEDIUM","LOW")))) -> NONE
A3: SEC00002 | B3: Atlas Capital 2 | C3: Corporate Bond | D3: USD | E3: 110.0662 | F3: 108.8043 | G3: 108.977 | H3: 1 | I3: 2331953 | J3: 140.1 | K3: =(PricingDataTable[[#This Row],[Current Price ($)]]-PricingDataTable[[#This Row],[Prior Price ($)]])/PricingDataTable[[#This Row],[Prior Price ($)]] -> -0.011464918 | L3: =(PricingDataTable[[#This Row],[Vendor Price ($)]]-PricingDataTable[[#This Row],[Current Price ($)]])/PricingDataTable[[#This Row],[Current Price ($)]] -> 0.0015872534 | M3: =IF(OR(F3="",F3=0),"MISSING",IF(H3>=3,"STALE",IF(ABS(K3)>=5%,"LARGE MOVE",IF(ABS(L3)>=2%,"VENDOR DIFFERENCE","PASS")))) -> PASS | N3: =IF(M3="PASS","NONE",IF(M3="MISSING","HIGH",IF(OR(ABS(K3)>=10%,ABS(L3)>=5%),"HIGH",IF(OR(ABS(K3)>=7%,ABS(L3)>=3%,H3>=5),"MEDIUM","LOW")))) -> NONE
A4: SEC00003 | B4: Liberty Capital 3 | C4: Equity | D4: USD | E4: 297.8431 | F4: 292.6878 | G4: 291.7216 | H4: 4 | I4: 3034614 | J4: 519.7 | K4: =(PricingDataTable[[#This Row],[Current Price ($)]]-PricingDataTable[[#This Row],[Prior Price ($)]])/PricingDataTable[[#This Row],[Prior Price ($)]] -> -0.017308778 | L4: =(PricingDataTable[[#This Row],[Vendor Price ($)]]-PricingDataTable[[#This Row],[Current Price ($)]])/PricingDataTable[[#This Row],[Current Price ($)]] -> -0.0033011284 | M4: =IF(OR(F4="",F4=0),"MISSING",IF(H4>=3,"STALE",IF(ABS(K4)>=5%,"LARGE MOVE",IF(ABS(L4)>=2%,"VENDOR DIFFERENCE","PASS")))) -> STALE | N4: =IF(M4="PASS","NONE",IF(M4="MISSING","HIGH",IF(OR(ABS(K4)>=10%,ABS(L4)>=5%),"HIGH",IF(OR(ABS(K4)>=7%,ABS(L4)>=3%,H4>=5),"MEDIUM","LOW")))) -> LOW
A5: SEC00004 | B5: Liberty Capital 4 | C5: Equity | D5: USD | E5: 106.9707 | F5: 107.7902 | G5: 107.9033 | H5: 0 | I5: 1758472 | J5: 603.22 | K5: =(PricingDataTable[[#This Row],[Current Price ($)]]-PricingDataTable[[#This Row],[Prior Price ($)]])/PricingDataTable[[#This Row],[Prior Price ($)]] -> 0.0076609763 | L5: =(PricingDataTable[[#This Row],[Vendor Price ($)]]-PricingDataTable[[#This Row],[Current Price ($)]])/PricingDataTable[[#This Row],[Current Price ($)]] -> 0.0010492605 | M5: =IF(OR(F5="",F5=0),"MISSING",IF(H5>=3,"STALE",IF(ABS(K5)>=5%,"LARGE MOVE",IF(ABS(L5)>=2%,"VENDOR DIFFERENCE","PASS")))) -> PASS | N5: =IF(M5="PASS","NONE",IF(M5="MISSING","HIGH",IF(OR(ABS(K5)>=10%,ABS(L5)>=5%),"HIGH",IF(OR(ABS(K5)>=7%,ABS(L5)>=3%,H5>=5),"MEDIUM","LOW")))) -> NONE
A6: SEC00005 | B6: Alpha Energy 5 | C6: Government Bond | D6: USD | E6: 111.4563 | F6: 112.1327 | G6: 112.4139 | H6: 0 | I6: 470241 | J6: 206.3 | K6: =(PricingDataTable[[#This Row],[Current Price ($)]]-PricingDataTable[[#This Row],[Prior Price ($)]])/PricingDataTable[[#This Row],[Prior Price ($)]] -> 0.0060687462 | L6: =(PricingDataTable[[#This Row],[Vendor Price ($)]]-PricingDataTable[[#This Row],[Current Price ($)]])/PricingDataTable[[#This Row],[Current Price ($)]] -> 0.0025077431 | M6: =IF(OR(F6="",F6=0),"MISSING",IF(H6>=3,"STALE",IF(ABS(K6)>=5%,"LARGE MOVE",IF(ABS(L6)>=2%,"VENDOR DIFFERENCE","PASS")))) -> PASS | N6: =IF(M6="PASS","NONE",IF(M6="MISSING","HIGH",IF(OR(ABS(K6)>=10%,ABS(L6)>=5%),"HIGH",IF(OR(ABS(K6)>=7%,ABS(L6)>=3%,H6>=5),"MEDIUM","LOW")))) -> NONE
A7: SEC00006 | B7: Vertex Markets 6 | C7: Corporate Bond | D7: USD | E7: 120.6568 | F7: 118.5555 | G7: 118.3237 | H7: 2 | I7: 1172304 | J7: 222.12 | K7: =(PricingDataTable[[#This Row],[Current Price ($)]]-PricingDataTable[[#This Row],[Prior Price ($)]])/PricingDataTable[[#This Row],[Prior Price ($)]] -> -0.017415512 | L7: =(PricingDataTable[[#This Row],[Vendor Price ($)]]-PricingDataTable[[#This Row],[Current Price ($)]])/PricingDataTable[[#This Row],[Current Price ($)]] -> -0.0019552024 | M7: =IF(OR(F7="",F7=0),"MISSING",IF(H7>=3,"STALE",IF(ABS(K7)>=5%,"LARGE MOVE",IF(ABS(L7)>=2%,"VENDOR DIFFERENCE","PASS")))) -> PASS | N7: =IF(M7="PASS","NONE",IF(M7="MISSING","HIGH",IF(OR(ABS(K7)>=10%,ABS(L7)>=5%),"HIGH",IF(OR(ABS(K7)>=7%,ABS(L7)>=3%,H7>=5),"MEDIUM","LOW")))) -> NONE
A8: SEC00007 | B8: Cedar Partners 7 | C8: Equity | D8: USD | E8: 315.0554 | F8: 312.909 | G8: 313.2993 | H8: 0 | I8: 1343026 | J8: 712.91 | K8: =(PricingDataTable[[#This Row],[Current Price ($)]]-PricingDataTable[[#This Row],[Prior Price ($)]])/PricingDataTable[[#This Row],[Prior Price ($)]] -> -0.0068127701 | L8: =(PricingDataTable[[#This Row],[Vendor Price ($)]]-PricingDataTable[[#This Row],[Current Price ($)]])/PricingDataTable[[#This Row],[Current Price ($)]] -> 0.0012473275 | M8: =IF(OR(F8="",F8=0),"MISSING",IF(H8>=3,"STALE",IF(ABS(K8)>=5%,"LARGE MOVE",IF(ABS(L8)>=2%,"VENDOR DIFFERENCE","PASS")))) -> PASS | N8: =IF(M8="PASS","NONE",IF(M8="MISSING","HIGH",IF(OR(ABS(K8)>=10%,ABS(L8)>=5%),"HIGH",IF(OR(ABS(K8)>=7%,ABS(L8)>=3%,H8>=5),"MEDIUM","LOW")))) -> NONE
A9: SEC00008 | B9: Nova Fund 8 | C9: Equity | D9: USD | E9: 348.6735 | F9: 337.7213 | G9: 306.9159 | H9: 0 | I9: 936767 | J9: 264.29 | K9: =(PricingDataTable[[#This Row],[Current Price ($)]]-PricingDataTable[[#This Row],[Prior Price ($)]])/PricingDataTable[[#This Row],[Prior Price ($)]] -> -0.031411048 | L9: =(PricingDataTable[[#This Row],[Vendor Price ($)]]-PricingDataTable[[#This Row],[Current Price ($)]])/PricingDataTable[[#This Row],[Current Price ($)]] -> -0.091215449 | M9: =IF(OR(F9="",F9=0),"MISSING",IF(H9>=3,"STALE",IF(ABS(K9)>=5%,"LARGE MOVE",IF(ABS(L9)>=2%,"VENDOR DIFFERENCE","PASS")))) -> VENDOR DIFFERENCE | N9: =IF(M9="PASS","NONE",IF(M9="MISSING","HIGH",IF(OR(ABS(K9)>=10%,ABS(L9)>=5%),"HIGH",IF(OR(ABS(K9)>=7%,ABS(L9)>=3%,H9>=5),"MEDIUM","LOW")))) -> HIGH
A10: SEC00009 | B10: Nova Markets 9 | C10: Equity | D10: EUR | E10: 254.1308 | F10: 259.2173 | G10: 258.9858 | H10: 0 | I10: 1669587 | J10: 137.72 | K10: =(PricingDataTable[[#This Row],[Current Price ($)]]-PricingDataTable[[#This Row],[Prior Price ($)]])/PricingDataTable[[#This Row],[Prior Price ($)]] -> 0.020015283 | L10: =(PricingDataTable[[#This Row],[Vendor Price ($)]]-PricingDataTable[[#This Row],[Current Price ($)]])/PricingDataTable[[#This Row],[Current Price ($)]] -> -0.00089307311 | M10: =IF(OR(F10="",F10=0),"MISSING",IF(H10>=3,"STALE",IF(ABS(K10)>=5%,"LARGE MOVE",IF(ABS(L10)>=2%,"VENDOR DIFFERENCE","PASS")))) -> PASS | N10: =IF(M10="PASS","NONE",IF(M10="MISSING","HIGH",IF(OR(ABS(K10)>=10%,ABS(L10)>=5%),"HIGH",IF(OR(ABS(K10)>=7%,ABS(L10)>=3%,H10>=5),"MEDIUM","LOW")))) -> NONE
A11: SEC00010 | B11: Orion Capital 10 | C11: Derivative | D11: JPY | E11: 165.4918 | F11: 163.6223 | G11: 163.2912 | H11: 5 | I11: 2021577 | J11: 790.23 | K11: =(PricingDataTable[[#This Row],[Current Price ($)]]-PricingDataTable[[#This Row],[Prior Price ($)]])/PricingDataTable[[#This Row],[Prior Price ($)]] -> -0.011296632 | L11: =(PricingDataTable[[#This Row],[Vendor Price ($)]]-PricingDataTable[[#This Row],[Current Price ($)]])/PricingDataTable[[#This Row],[Current Price ($)]] -> -0.0020235628 | M11: =IF(OR(F11="",F11=0),"MISSING",IF(H11>=3,"STALE",IF(ABS(K11)>=5%,"LARGE MOVE",IF(ABS(L11)>=2%,"VENDOR DIFFERENCE","PASS")))) -> STALE | N11: =IF(M11="PASS","NONE",IF(M11="MISSING","HIGH",IF(OR(ABS(K11)>=10%,ABS(L11)>=5%),"HIGH",IF(OR(ABS(K11)>=7%,ABS(L11)>=3%,H11>=5),"MEDIUM","LOW")))) -> MEDIUM
A12: SEC00011 | B12: Liberty Group 11 | C12: ETF | D12: EUR | E12: 342.4707 | F12: 340.3848 | G12: 340.2768 | H12: 0 | I12: 1777692 | J12: 836.04 | K12: =(PricingDataTable[[#This Row],[Current Price ($)]]-PricingDataTable[[#This Row],[Prior Price ($)]])/PricingDataTable[[#This Row],[Prior Price ($)]] -> -0.00609074 | L12: =(PricingDataTable[[#This Row],[Vendor Price ($)]]-PricingDataTable[[#This Row],[Current Price ($)]])/PricingDataTable[[#This Row],[Current Price ($)]] -> -0.00031728796 | M12: =IF(OR(F12="",F12=0),"MISSING",IF(H12>=3,"STALE",IF(ABS(K12)>=5%,"LARGE MOVE",IF(ABS(L12)>=2%,"VENDOR DIFFERENCE","PASS")))) -> PASS | N12: =IF(M12="PASS","NONE",IF(M12="MISSING","HIGH",IF(OR(ABS(K12)>=10%,ABS(L12)>=5%),"HIGH",IF(OR(ABS(K12)>=7%,ABS(L12)>=3%,H12>=5),"MEDIUM","LOW")))) -> NONE
A13: SEC00012 | B13: Orion Holdings 12 | C13: Government Bond | D13: USD | E13: 108.5843 | F13: 106.6285 | G13: 107.1183 | H13: 0 | I13: 4937193 | J13: 198.35 | K13: =(PricingDataTable[[#This Row],[Current Price ($)]]-PricingDataTable[[#This Row],[Prior Price ($)]])/PricingDataTable[[#This Row],[Prior Price ($)]] -> -0.018011812 | L13: =(PricingDataTable[[#This Row],[Vendor Price ($)]]-PricingDataTable[[#This Row],[Current Price ($)]])/PricingDataTable[[#This Row],[Current Price ($)]] -> 0.0045935186 | M13: =IF(OR(F13="",F13=0),"MISSING",IF(H13>=3,"STALE",IF(ABS(K13)>=5%,"LARGE MOVE",IF(ABS(L13)>=2%,"VENDOR DIFFERENCE","PASS")))) -> PASS | N13: =IF(M13="PASS","NONE",IF(M13="MISSING","HIGH",IF(OR(ABS(K13)>=10%,ABS(L13)>=5%),"HIGH",IF(OR(ABS(K13)>=7%,ABS(L13)>=3%,H13>=5),"MEDIUM","LOW")))) -> NONE
... A205: SEC00204 | B205: Delta Markets 204 | C205: ETF | D205: USD | E205: 37.5438 | F205: 37.1274 | G205: 37.1561 | H205: 1 | I205: 4139609 | J205: 898.01 | K205: =(PricingDataTable[[#This Row],[Current Price ($)]]-PricingDataTable[[#This Row],[Prior Price ($)]])/PricingDataTable[[#This Row],[Prior Price ($)]] -> -0.011091046 | L205: =(PricingDataTable[[#This Row],[Vendor Price ($)]]-PricingDataTable[[#This Row],[Current Price ($)]])/PricingDataTable[[#This Row],[Current Price ($)]] -> 0.000773014 | M205: =IF(OR(F205="",F205=0),"MISSING",IF(H205>=3,"STALE",IF(ABS(K205)>=5%,"LARGE MOVE",IF(ABS(L205)>=2%,"VENDOR DIFFERENCE","PASS")))) -> PASS | N205: =IF(M205="PASS","NONE",IF(M205="MISSING","HIGH",IF(OR(ABS(K205)>=10%,ABS(L205)>=5%),"HIGH",IF(OR(ABS(K205)>=7%,ABS(L205)>=3%,H205>=5),"MEDIUM","LOW")))) -> NONE
A206: SEC00205 | B206: Liberty Financial 205 | C206: ETF | D206: USD | E206: 10.1812 | F206: 10.1061 | H206: 2 | I206: 3157422 | J206: 764.14 | K206: =(PricingDataTable[[#This Row],[Current Price ($)]]-PricingDataTable[[#This Row],[Prior Price ($)]])/PricingDataTable[[#This Row],[Prior Price ($)]] -> -0.0073763407 | L206: =(PricingDataTable[[#This Row],[Vendor Price ($)]]-PricingDataTable[[#This Row],[Current Price ($)]])/PricingDataTable[[#This Row],[Current Price ($)]] -> -1 | M206: =IF(OR(F206="",F206=0),"MISSING",IF(H206>=3,"STALE",IF(ABS(K206)>=5%,"LARGE MOVE",IF(ABS(L206)>=2%,"VENDOR DIFFERENCE","PASS")))) -> VENDOR DIFFERENCE | N206: =IF(M206="PASS","NONE",IF(M206="MISSING","HIGH",IF(OR(ABS(K206)>=10%,ABS(L206)>=5%),"HIGH",IF(OR(ABS(K206)>=7%,ABS(L206)>=3%,H206>=5),"MEDIUM","LOW")))) -> HIGH
A207: SEC00206 | B207: Atlas Fund 206 | C207: Equity | D207: USD | E207: 89.4533 | F207: 89.0765 | G207: 89.0812 | H207: 0 | I207: 4361056 | J207: 371.87 | K207: =(PricingDataTable[[#This Row],[Current Price ($)]]-PricingDataTable[[#This Row],[Prior Price ($)]])/PricingDataTable[[#This Row],[Prior Price ($)]] -> -0.0042122538 | L207: =(PricingDataTable[[#This Row],[Vendor Price ($)]]-PricingDataTable[[#This Row],[Current Price ($)]])/PricingDataTable[[#This Row],[Current Price ($)]] -> 5.2763636e-05 | M207: =IF(OR(F207="",F207=0),"MISSING",IF(H207>=3,"STALE",IF(ABS(K207)>=5%,"LARGE MOVE",IF(ABS(L207)>=2%,"VENDOR DIFFERENCE","PASS")))) -> PASS | N207: =IF(M207="PASS","NONE",IF(M207="MISSING","HIGH",IF(OR(ABS(K207)>=10%,ABS(L207)>=5%),"HIGH",IF(OR(ABS(K207)>=7%,ABS(L207)>=3%,H207>=5),"MEDIUM","LOW")))) -> NONE
A208: SEC00207 | B208: Cedar Energy 207 | C208: Derivative | D208: USD | E208: 19.0127 | F208: 19.2951 | G208: 19.3748 | H208: 0 | I208: 2190350 | J208: 765.85 | K208: =(PricingDataTable[[#This Row],[Current Price ($)]]-PricingDataTable[[#This Row],[Prior Price ($)]])/PricingDataTable[[#This Row],[Prior Price ($)]] -> 0.01485323 | L208: =(PricingDataTable[[#This Row],[Vendor Price ($)]]-PricingDataTable[[#This Row],[Current Price ($)]])/PricingDataTable[[#This Row],[Current Price ($)]] -> 0.0041305824 | M208: =IF(OR(F208="",F208=0),"MISSING",IF(H208>=3,"STALE",IF(ABS(K208)>=5%,"LARGE MOVE",IF(ABS(L208)>=2%,"VENDOR DIFFERENCE","PASS")))) -> PASS | N208: =IF(M208="PASS","NONE",IF(M208="MISSING","HIGH",IF(OR(ABS(K208)>=10%,ABS(L208)>=5%),"HIGH",IF(OR(ABS(K208)>=7%,ABS(L208)>=3%,H208>=5),"MEDIUM","LOW")))) -> NONE
A209: SEC00208 | B209: Delta Fund 208 | C209: Equity | D209: USD | E209: 33.5431 | F209: 33.7482 | G209: 33.9166 | H209: 0 | I209: 4496660 | J209: 322.59 | K209: =(PricingDataTable[[#This Row],[Current Price ($)]]-PricingDataTable[[#This Row],[Prior Price ($)]])/PricingDataTable[[#This Row],[Prior Price ($)]] -> 0.0061145213 | L209: =(PricingDataTable[[#This Row],[Vendor Price ($)]]-PricingDataTable[[#This Row],[Current Price ($)]])/PricingDataTable[[#This Row],[Current Price ($)]] -> 0.0049898958 | M209: =IF(OR(F209="",F209=0),"MISSING",IF(H209>=3,"STALE",IF(ABS(K209)>=5%,"LARGE MOVE",IF(ABS(L209)>=2%,"VENDOR DIFFERENCE","PASS")))) -> PASS | N209: =IF(M209="PASS","NONE",IF(M209="MISSING","HIGH",IF(OR(ABS(K209)>=10%,ABS(L209)>=5%),"HIGH",IF(OR(ABS(K209)>=7%,ABS(L209)>=3%,H209>=5),"MEDIUM","LOW")))) -> NONE
A210: SEC00209 | B210: Atlas Technology 209 | C210: Equity | D210: USD | E210: 49.0104 | F210: 49.5014 | G210: 49.6904 | H210: 0 | I210: 766149 | J210: 640.1 | K210: =(PricingDataTable[[#This Row],[Current Price ($)]]-PricingDataTable[[#This Row],[Prior Price ($)]])/PricingDataTable[[#This Row],[Prior Price ($)]] -> 0.010018282 | L210: =(PricingDataTable[[#This Row],[Vendor Price ($)]]-PricingDataTable[[#This Row],[Current Price ($)]])/PricingDataTable[[#This Row],[Current Price ($)]] -> 0.0038180738 | M210: =IF(OR(F210="",F210=0),"MISSING",IF(H210>=3,"STALE",IF(ABS(K210)>=5%,"LARGE MOVE",IF(ABS(L210)>=2%,"VENDOR DIFFERENCE","PASS")))) -> PASS | N210: =IF(M210="PASS","NONE",IF(M210="MISSING","HIGH",IF(OR(ABS(K210)>=10%,ABS(L210)>=5%),"HIGH",IF(OR(ABS(K210)>=7%,ABS(L210)>=3%,H210>=5),"MEDIUM","LOW")))) -> NONE
A211: SEC00210 | B211: Alpha Group 210 | C211: Corporate Bond | D211: USD | E211: 88.0083 | F211: 88.2733 | G211: 88.2694 | H211: 1 | I211: 1173669 | J211: 109.48 | K211: =(PricingDataTable[[#This Row],[Current Price ($)]]-PricingDataTable[[#This Row],[Prior Price ($)]])/PricingDataTable[[#This Row],[Prior Price ($)]] -> 0.0030110796 | L211: =(PricingDataTable[[#This Row],[Vendor Price ($)]]-PricingDataTable[[#This Row],[Current Price ($)]])/PricingDataTable[[#This Row],[Current Price ($)]] -> -4.418097e-05 | M211: =IF(OR(F211="",F211=0),"MISSING",IF(H211>=3,"STALE",IF(ABS(K211)>=5%,"LARGE MOVE",IF(ABS(L211)>=2%,"VENDOR DIFFERENCE","PASS")))) -> PASS | N211: =IF(M211="PASS","NONE",IF(M211="MISSING","HIGH",IF(OR(ABS(K211)>=10%,ABS(L211)>=5%),"HIGH",IF(OR(ABS(K211)>=7%,ABS(L211)>=3%,H211>=5),"MEDIUM","LOW")))) -> NONE
A212: SEC00211 | B212: Orion Energy 211 | C212: Equity | D212: GBP | E212: 135.306 | F212: 133.7102 | G212: 133.2888 | H212: 1 | I212: 3720771 | J212: 728.41 | K212: =(PricingDataTable[[#This Row],[Current Price ($)]]-PricingDataTable[[#This Row],[Prior Price ($)]])/PricingDataTable[[#This Row],[Prior Price ($)]] -> -0.011794008 | L212: =(PricingDataTable[[#This Row],[Vendor Price ($)]]-PricingDataTable[[#This Row],[Current Price ($)]])/PricingDataTable[[#This Row],[Current Price ($)]] -> -0.003151592 | M212: =IF(OR(F212="",F212=0),"MISSING",IF(H212>=3,"STALE",IF(ABS(K212)>=5%,"LARGE MOVE",IF(ABS(L212)>=2%,"VENDOR DIFFERENCE","PASS")))) -> PASS | N212: =IF(M212="PASS","NONE",IF(M212="MISSING","HIGH",IF(OR(ABS(K212)>=10%,ABS(L212)>=5%),"HIGH",IF(OR(ABS(K212)>=7%,ABS(L212)>=3%,H212>=5),"MEDIUM","LOW")))) -> NONE
A213: SEC00212 | B213: Pioneer Industries 212 | C213: Equity | D213: JPY | E213: 25.3181 | F213: 25.6057 | G213: 25.5682 | H213: 0 | I213: 1570937 | J213: 247.63 | K213: =(PricingDataTable[[#This Row],[Current Price ($)]]-PricingDataTable[[#This Row],[Prior Price ($)]])/PricingDataTable[[#This Row],[Prior Price ($)]] -> 0.011359462 | L213: =(PricingDataTable[[#This Row],[Vendor Price ($)]]-PricingDataTable[[#This Row],[Current Price ($)]])/PricingDataTable[[#This Row],[Current Price ($)]] -> -0.0014645177 | M213: =IF(OR(F213="",F213=0),"MISSING",IF(H213>=3,"STALE",IF(ABS(K213)>=5%,"LARGE MOVE",IF(ABS(L213)>=2%,"VENDOR DIFFERENCE","PASS")))) -> PASS | N213: =IF(M213="PASS","NONE",IF(M213="MISSING","HIGH",IF(OR(ABS(K213)>=10%,ABS(L213)>=5%),"HIGH",IF(OR(ABS(K213)>=7%,ABS(L213)>=3%,H213>=5),"MEDIUM","LOW")))) -> NONE
A214: SEC00213 | B214: Vertex Holdings 213 | C214: Equity | D214: USD | E214: 92.0584 | F214: 91.7401 | G214: 92.0124 | H214: 0 | I214: 4411848 | J214: 224.38 | K214: =(PricingDataTable[[#This Row],[Current Price ($)]]-PricingDataTable[[#This Row],[Prior Price ($)]])/PricingDataTable[[#This Row],[Prior Price ($)]] -> -0.0034575878 | L214: =(PricingDataTable[[#This Row],[Vendor Price ($)]]-PricingDataTable[[#This Row],[Current Price ($)]])/PricingDataTable[[#This Row],[Current Price ($)]] -> 0.0029681677 | M214: =IF(OR(F214="",F214=0),"MISSING",IF(H214>=3,"STALE",IF(ABS(K214)>=5%,"LARGE MOVE",IF(ABS(L214)>=2%,"VENDOR DIFFERENCE","PASS")))) -> PASS | N214: =IF(M214="PASS","NONE",IF(M214="MISSING","HIGH",IF(OR(ABS(K214)>=10%,ABS(L214)>=5%),"HIGH",IF(OR(ABS(K214)>=7%,ABS(L214)>=3%,H214>=5),"MEDIUM","LOW")))) -> NONE
A215: SEC00214 | B215: Summit Holdings 214 | C215: Derivative | D215: EUR | E215: 65.922 | F215: 65.0465 | G215: 64.9844 | H215: 0 | I215: 1838274 | J215: 26.57 | K215: =(PricingDataTable[[#This Row],[Current Price ($)]]-PricingDataTable[[#This Row],[Prior Price ($)]])/PricingDataTable[[#This Row],[Prior Price ($)]] -> -0.013280847 | L215: =(PricingDataTable[[#This Row],[Vendor Price ($)]]-PricingDataTable[[#This Row],[Current Price ($)]])/PricingDataTable[[#This Row],[Current Price ($)]] -> -0.00095470164 | M215: =IF(OR(F215="",F215=0),"MISSING",IF(H215>=3,"STALE",IF(ABS(K215)>=5%,"LARGE MOVE",IF(ABS(L215)>=2%,"VENDOR DIFFERENCE","PASS")))) -> PASS | N215: =IF(M215="PASS","NONE",IF(M215="MISSING","HIGH",IF(OR(ABS(K215)>=10%,ABS(L215)>=5%),"HIGH",IF(OR(ABS(K215)>=7%,ABS(L215)>=3%,H215>=5),"MEDIUM","LOW")))) -> NONE
A216: SEC00215 | B216: Delta Partners 215 | C216: ETF | D216: USD | E216: 130.242 | F216: 129.2591 | G216: 129.117 | H216: 0 | I216: 469995 | J216: 687.69 | K216: =(PricingDataTable[[#This Row],[Current Price ($)]]-PricingDataTable[[#This Row],[Prior Price ($)]])/PricingDataTable[[#This Row],[Prior Price ($)]] -> -0.0075467207 | L216: =(PricingDataTable[[#This Row],[Vendor Price ($)]]-PricingDataTable[[#This Row],[Current Price ($)]])/PricingDataTable[[#This Row],[Current Price ($)]] -> -0.0010993423 | M216: =IF(OR(F216="",F216=0),"MISSING",IF(H216>=3,"STALE",IF(ABS(K216)>=5%,"LARGE MOVE",IF(ABS(L216)>=2%,"VENDOR DIFFERENCE","PASS")))) -> PASS | N216: =IF(M216="PASS","NONE",IF(M216="MISSING","HIGH",IF(OR(ABS(K216)>=10%,ABS(L216)>=5%),"HIGH",IF(OR(ABS(K216)>=7%,ABS(L216)>=3%,H216>=5),"MEDIUM","LOW")))) -> NONE
A217: SEC00216 | B217: Atlas Partners 216 | C217: ETF | D217: EUR | E217: 129.3432 | F217: 130.9373 | G217: 130.2947 | H217: 1 | I217: 237613 | J217: 633.17 | K217: =(PricingDataTable[[#This Row],[Current Price ($)]]-PricingDataTable[[#This Row],[Prior Price ($)]])/PricingDataTable[[#This Row],[Prior Price ($)]] -> 0.012324575 | L217: =(PricingDataTable[[#This Row],[Vendor Price ($)]]-PricingDataTable[[#This Row],[Current Price ($)]])/PricingDataTable[[#This Row],[Current Price ($)]] -> -0.0049076925 | M217: =IF(OR(F217="",F217=0),"MISSING",IF(H217>=3,"STALE",IF(ABS(K217)>=5%,"LARGE MOVE",IF(ABS(L217)>=2%,"VENDOR DIFFERENCE","PASS")))) -> PASS | N217: =IF(M217="PASS","NONE",IF(M217="MISSING","HIGH",IF(OR(ABS(K217)>=10%,ABS(L217)>=5%),"HIGH",IF(OR(ABS(K217)>=7%,ABS(L217)>=3%,H217>=5),"MEDIUM","LOW")))) -> NONE
A218: SEC00217 | B218: Pioneer Holdings 217 | C218: Corporate Bond | D218: USD | E218: 84.4117 | F218: 86.4983 | G218: 86.458 | H218: 0 | I218: 1836502 | J218: 18.13 | K218: =(PricingDataTable[[#This Row],[Current Price ($)]]-PricingDataTable[[#This Row],[Prior Price ($)]])/PricingDataTable[[#This Row],[Prior Price ($)]] -> 0.024719322 | L218: =(PricingDataTable[[#This Row],[Vendor Price ($)]]-PricingDataTable[[#This Row],[Current Price ($)]])/PricingDataTable[[#This Row],[Current Price ($)]] -> -0.00046590511 | M218: =IF(OR(F218="",F218=0),"MISSING",IF(H218>=3,"STALE",IF(ABS(K218)>=5%,"LARGE MOVE",IF(ABS(L218)>=2%,"VENDOR DIFFERENCE","PASS")))) -> PASS | N218: =IF(M218="PASS","NONE",IF(M218="MISSING","HIGH",IF(OR(ABS(K218)>=10%,ABS(L218)>=5%),"HIGH",IF(OR(ABS(K218)>=7%,ABS(L218)>=3%,H218>=5),"MEDIUM","LOW")))) -> NONE
... A247: SEC00246 | B247: Cedar Technology 246 | C247: Equity | D247: USD | E247: 162.6022 | F247: 163.4512 | G247: 164.2689 | H247: 1 | I247: 3639235 | J247: 570.21 | K247: =(PricingDataTable[[#This Row],[Current Price ($)]]-PricingDataTable[[#This Row],[Prior Price ($)]])/PricingDataTable[[#This Row],[Prior Price ($)]] -> 0.0052213316 | L247: =(PricingDataTable[[#This Row],[Vendor Price ($)]]-PricingDataTable[[#This Row],[Current Price ($)]])/PricingDataTable[[#This Row],[Current Price ($)]] -> 0.0050027164 | M247: =IF(OR(F247="",F247=0),"MISSING",IF(H247>=3,"STALE",IF(ABS(K247)>=5%,"LARGE MOVE",IF(ABS(L247)>=2%,"VENDOR DIFFERENCE","PASS")))) -> PASS | N247: =IF(M247="PASS","NONE",IF(M247="MISSING","HIGH",IF(OR(ABS(K247)>=10%,ABS(L247)>=5%),"HIGH",IF(OR(ABS(K247)>=7%,ABS(L247)>=3%,H247>=5),"MEDIUM","LOW")))) -> NONE
A248: SEC00247 | B248: Atlas Financial 247 | C248: Derivative | D248: USD | E248: 8.7151 | G248: 10.3321 | H248: 0 | I248: 1899054 | J248: 624.23 | K248: =(PricingDataTable[[#This Row],[Current Price ($)]]-PricingDataTable[[#This Row],[Prior Price ($)]])/PricingDataTable[[#This Row],[Prior Price ($)]] -> -1 | L248: =(PricingDataTable[[#This Row],[Vendor Price ($)]]-PricingDataTable[[#This Row],[Current Price ($)]])/PricingDataTable[[#This Row],[Current Price ($)]] -> #DIV/0! | M248: =IF(OR(F248="",F248=0),"MISSING",IF(H248>=3,"STALE",IF(ABS(K248)>=5%,"LARGE MOVE",IF(ABS(L248)>=2%,"VENDOR DIFFERENCE","PASS")))) -> MISSING | N248: =IF(M248="PASS","NONE",IF(M248="MISSING","HIGH",IF(OR(ABS(K248)>=10%,ABS(L248)>=5%),"HIGH",IF(OR(ABS(K248)>=7%,ABS(L248)>=3%,H248>=5),"MEDIUM","LOW")))) -> HIGH
A249: SEC00248 | B249: Pioneer Energy 248 | C249: Equity | D249: USD | E249: 209.3254 | F249: 211.6569 | G249: 212.6829 | H249: 1 | I249: 1123307 | J249: 308.59 | K249: =(PricingDataTable[[#This Row],[Current Price ($)]]-PricingDataTable[[#This Row],[Prior Price ($)]])/PricingDataTable[[#This Row],[Prior Price ($)]] -> 0.011138161 | L249: =(PricingDataTable[[#This Row],[Vendor Price ($)]]-PricingDataTable[[#This Row],[Current Price ($)]])/PricingDataTable[[#This Row],[Current Price ($)]] -> 0.0048474678 | M249: =IF(OR(F249="",F249=0),"MISSING",IF(H249>=3,"STALE",IF(ABS(K249)>=5%,"LARGE MOVE",IF(ABS(L249)>=2%,"VENDOR DIFFERENCE","PASS")))) -> PASS | N249: =IF(M249="PASS","NONE",IF(M249="MISSING","HIGH",IF(OR(ABS(K249)>=10%,ABS(L249)>=5%),"HIGH",IF(OR(ABS(K249)>=7%,ABS(L249)>=3%,H249>=5),"MEDIUM","LOW")))) -> NONE
A250: SEC00249 | B250: Sterling Holdings 249 | C250: ETF | D250: USD | E250: 318.1578 | F250: 318.4428 | G250: 318.2691 | H250: 0 | I250: 1034157 | J250: 330.06 | K250: =(PricingDataTable[[#This Row],[Current Price ($)]]-PricingDataTable[[#This Row],[Prior Price ($)]])/PricingDataTable[[#This Row],[Prior Price ($)]] -> 0.0008957819 | L250: =(PricingDataTable[[#This Row],[Vendor Price ($)]]-PricingDataTable[[#This Row],[Current Price ($)]])/PricingDataTable[[#This Row],[Current Price ($)]] -> -0.00054546688 | M250: =IF(OR(F250="",F250=0),"MISSING",IF(H250>=3,"STALE",IF(ABS(K250)>=5%,"LARGE MOVE",IF(ABS(L250)>=2%,"VENDOR DIFFERENCE","PASS")))) -> PASS | N250: =IF(M250="PASS","NONE",IF(M250="MISSING","HIGH",IF(OR(ABS(K250)>=10%,ABS(L250)>=5%),"HIGH",IF(OR(ABS(K250)>=7%,ABS(L250)>=3%,H250>=5),"MEDIUM","LOW")))) -> NONE
A251: SEC00250 | B251: Vertex Financial 250 | C251: Corporate Bond | D251: USD | E251: 113.5625 | F251: 112.2537 | G251: 111.9378 | H251: 1 | I251: 3728178 | J251: 342.35 | K251: =(PricingDataTable[[#This Row],[Current Price ($)]]-PricingDataTable[[#This Row],[Prior Price ($)]])/PricingDataTable[[#This Row],[Prior Price ($)]] -> -0.011524931 | L251: =(PricingDataTable[[#This Row],[Vendor Price ($)]]-PricingDataTable[[#This Row],[Current Price ($)]])/PricingDataTable[[#This Row],[Current Price ($)]] -> -0.0028141611 | M251: =IF(OR(F251="",F251=0),"MISSING",IF(H251>=3,"STALE",IF(ABS(K251)>=5%,"LARGE MOVE",IF(ABS(L251)>=2%,"VENDOR DIFFERENCE","PASS")))) -> PASS | N251: =IF(M251="PASS","NONE",IF(M251="MISSING","HIGH",IF(OR(ABS(K251)>=10%,ABS(L251)>=5%),"HIGH",IF(OR(ABS(K251)>=7%,ABS(L251)>=3%,H251>=5),"MEDIUM","LOW")))) -> NONE
A252: SEC00251 | B252: Harbor Capital 251 | C252: Corporate Bond | D252: USD | E252: 109.7596 | F252: 108.998 | G252: 108.7958 | H252: 0 | I252: 881084 | J252: 460.52 | K252: =(PricingDataTable[[#This Row],[Current Price ($)]]-PricingDataTable[[#This Row],[Prior Price ($)]])/PricingDataTable[[#This Row],[Prior Price ($)]] -> -0.0069388008 | L252: =(PricingDataTable[[#This Row],[Vendor Price ($)]]-PricingDataTable[[#This Row],[Current Price ($)]])/PricingDataTable[[#This Row],[Current Price ($)]] -> -0.0018550799 | M252: =IF(OR(F252="",F252=0),"MISSING",IF(H252>=3,"STALE",IF(ABS(K252)>=5%,"LARGE MOVE",IF(ABS(L252)>=2%,"VENDOR DIFFERENCE","PASS")))) -> PASS | N252: =IF(M252="PASS","NONE",IF(M252="MISSING","HIGH",IF(OR(ABS(K252)>=10%,ABS(L252)>=5%),"HIGH",IF(OR(ABS(K252)>=7%,ABS(L252)>=3%,H252>=5),"MEDIUM","LOW")))) -> NONE
A253: SEC00252 | B253: Delta Fund 252 | C253: Equity | D253: EUR | E253: 178.2268 | F253: 175.3531 | G253: 174.7757 | H253: 0 | I253: 4599121 | J253: 446.82 | K253: =(PricingDataTable[[#This Row],[Current Price ($)]]-PricingDataTable[[#This Row],[Prior Price ($)]])/PricingDataTable[[#This Row],[Prior Price ($)]] -> -0.016123838 | L253: =(PricingDataTable[[#This Row],[Vendor Price ($)]]-PricingDataTable[[#This Row],[Current Price ($)]])/PricingDataTable[[#This Row],[Current Price ($)]] -> -0.0032927847 | M253: =IF(OR(F253="",F253=0),"MISSING",IF(H253>=3,"STALE",IF(ABS(K253)>=5%,"LARGE MOVE",IF(ABS(L253)>=2%,"VENDOR DIFFERENCE","PASS")))) -> PASS | N253: =IF(M253="PASS","NONE",IF(M253="MISSING","HIGH",IF(OR(ABS(K253)>=10%,ABS(L253)>=5%),"HIGH",IF(OR(ABS(K253)>=7%,ABS(L253)>=3%,H253>=5),"MEDIUM","LOW")))) -> NONE
A254: SEC00253 | B254: Sterling Group 253 | C254: Equity | D254: USD | E254: 237.6985 | F254: 242.2144 | G254: 241.4523 | H254: 0 | I254: 850686 | J254: 814.32 | K254: =(PricingDataTable[[#This Row],[Current Price ($)]]-PricingDataTable[[#This Row],[Prior Price ($)]])/PricingDataTable[[#This Row],[Prior Price ($)]] -> 0.018998437 | L254: =(PricingDataTable[[#This Row],[Vendor Price ($)]]-PricingDataTable[[#This Row],[Current Price ($)]])/PricingDataTable[[#This Row],[Current Price ($)]] -> -0.003146386 | M254: =IF(OR(F254="",F254=0),"MISSING",IF(H254>=3,"STALE",IF(ABS(K254)>=5%,"LARGE MOVE",IF(ABS(L254)>=2%,"VENDOR DIFFERENCE","PASS")))) -> PASS | N254: =IF(M254="PASS","NONE",IF(M254="MISSING","HIGH",IF(OR(ABS(K254)>=10%,ABS(L254)>=5%),"HIGH",IF(OR(ABS(K254)>=7%,ABS(L254)>=3%,H254>=5),"MEDIUM","LOW")))) -> NONE
A255: SEC00254 | B255: Alpha Holdings 254 | C255: Corporate Bond | D255: CAD | E255: 88.2063 | F255: 90.0499 | G255: 90.203 | H255: 0 | I255: 973248 | J255: 85.68 | K255: =(PricingDataTable[[#This Row],[Current Price ($)]]-PricingDataTable[[#This Row],[Prior Price ($)]])/PricingDataTable[[#This Row],[Prior Price ($)]] -> 0.020901001 | L255: =(PricingDataTable[[#This Row],[Vendor Price ($)]]-PricingDataTable[[#This Row],[Current Price ($)]])/PricingDataTable[[#This Row],[Current Price ($)]] -> 0.0017001685 | M255: =IF(OR(F255="",F255=0),"MISSING",IF(H255>=3,"STALE",IF(ABS(K255)>=5%,"LARGE MOVE",IF(ABS(L255)>=2%,"VENDOR DIFFERENCE","PASS")))) -> PASS | N255: =IF(M255="PASS","NONE",IF(M255="MISSING","HIGH",IF(OR(ABS(K255)>=10%,ABS(L255)>=5%),"HIGH",IF(OR(ABS(K255)>=7%,ABS(L255)>=3%,H255>=5),"MEDIUM","LOW")))) -> NONE
A256: SEC00255 | B256: Pioneer Financial 255 | C256: ETF | D256: USD | E256: 66.3152 | F256: 65.7812 | G256: 65.9464 | H256: 0 | I256: 3362965 | J256: 360.35 | K256: =(PricingDataTable[[#This Row],[Current Price ($)]]-PricingDataTable[[#This Row],[Prior Price ($)]])/PricingDataTable[[#This Row],[Prior Price ($)]] -> -0.0080524525 | L256: =(PricingDataTable[[#This Row],[Vendor Price ($)]]-PricingDataTable[[#This Row],[Current Price ($)]])/PricingDataTable[[#This Row],[Current Price ($)]] -> 0.0025113558 | M256: =IF(OR(F256="",F256=0),"MISSING",IF(H256>=3,"STALE",IF(ABS(K256)>=5%,"LARGE MOVE",IF(ABS(L256)>=2%,"VENDOR DIFFERENCE","PASS")))) -> PASS | N256: =IF(M256="PASS","NONE",IF(M256="MISSING","HIGH",IF(OR(ABS(K256)>=10%,ABS(L256)>=5%),"HIGH",IF(OR(ABS(K256)>=7%,ABS(L256)>=3%,H256>=5),"MEDIUM","LOW")))) -> NONE
A257: SEC00256 | B257: Harbor Fund 256 | C257: ETF | D257: USD | E257: 171.5598 | F257: 167.7768 | G257: 168.2722 | H257: 1 | I257: 871008 | J257: 374.54 | K257: =(PricingDataTable[[#This Row],[Current Price ($)]]-PricingDataTable[[#This Row],[Prior Price ($)]])/PricingDataTable[[#This Row],[Prior Price ($)]] -> -0.02205062 | L257: =(PricingDataTable[[#This Row],[Vendor Price ($)]]-PricingDataTable[[#This Row],[Current Price ($)]])/PricingDataTable[[#This Row],[Current Price ($)]] -> 0.0029527324 | M257: =IF(OR(F257="",F257=0),"MISSING",IF(H257>=3,"STALE",IF(ABS(K257)>=5%,"LARGE MOVE",IF(ABS(L257)>=2%,"VENDOR DIFFERENCE","PASS")))) -> PASS | N257: =IF(M257="PASS","NONE",IF(M257="MISSING","HIGH",IF(OR(ABS(K257)>=10%,ABS(L257)>=5%),"HIGH",IF(OR(ABS(K257)>=7%,ABS(L257)>=3%,H257>=5),"MEDIUM","LOW")))) -> NONE
A258: SEC00257 | B258: Sterling Markets 257 | C258: ETF | D258: USD | E258: 69.9911 | F258: 60.1675 | G258: 60.2841 | H258: 2 | I258: 2637018 | J258: 11.32 | K258: =(PricingDataTable[[#This Row],[Current Price ($)]]-PricingDataTable[[#This Row],[Prior Price ($)]])/PricingDataTable[[#This Row],[Prior Price ($)]] -> -0.14035499 | L258: =(PricingDataTable[[#This Row],[Vendor Price ($)]]-PricingDataTable[[#This Row],[Current Price ($)]])/PricingDataTable[[#This Row],[Current Price ($)]] -> 0.0019379233 | M258: =IF(OR(F258="",F258=0),"MISSING",IF(H258>=3,"STALE",IF(ABS(K258)>=5%,"LARGE MOVE",IF(ABS(L258)>=2%,"VENDOR DIFFERENCE","PASS")))) -> LARGE MOVE | N258: =IF(M258="PASS","NONE",IF(M258="MISSING","HIGH",IF(OR(ABS(K258)>=10%,ABS(L258)>=5%),"HIGH",IF(OR(ABS(K258)>=7%,ABS(L258)>=3%,H258>=5),"MEDIUM","LOW")))) -> HIGH
A259: SEC00258 | B259: Sterling Technology 258 | C259: ETF | D259: USD | E259: 201.2342 | F259: 204.7946 | G259: 204.668 | H259: 1 | I259: 2086214 | J259: 433.84 | K259: =(PricingDataTable[[#This Row],[Current Price ($)]]-PricingDataTable[[#This Row],[Prior Price ($)]])/PricingDataTable[[#This Row],[Prior Price ($)]] -> 0.017692818 | L259: =(PricingDataTable[[#This Row],[Vendor Price ($)]]-PricingDataTable[[#This Row],[Current Price ($)]])/PricingDataTable[[#This Row],[Current Price ($)]] -> -0.00061818036 | M259: =IF(OR(F259="",F259=0),"MISSING",IF(H259>=3,"STALE",IF(ABS(K259)>=5%,"LARGE MOVE",IF(ABS(L259)>=2%,"VENDOR DIFFERENCE","PASS")))) -> PASS | N259: =IF(M259="PASS","NONE",IF(M259="MISSING","HIGH",IF(OR(ABS(K259)>=10%,ABS(L259)>=5%),"HIGH",IF(OR(ABS(K259)>=7%,ABS(L259)>=3%,H259>=5),"MEDIUM","LOW")))) -> NONE
...

Sheet Project Guide
A1: SECURITY PRICING & VALUATION EXCEPTION ANALYSIS
A2: Purpose | B2: Practice portfolio project using fully fictional data. No employer/confidential data.
A3: Business Scenario | B3: Review a 5,000-security portfolio before NAV and identify records requiring pricing investigation.
A4: Your first task | B4: Open the Pricing Data sheet. Review the columns and use the filters to inspect records.
A5: Next step | B5: We will build the exception rules and formulas together rather than treating the finished logic as a black box.
A6: Fields included | B6: Security ID, Security Name, Asset Class, Currency, Prior Price, Current Price, Vendor Price, Price Age (Days), Volume, Market Value ($mm).

Sheet Dashboard
A1: Security Pricing & Valuation Dashboard
A3: Total Securities Reviewed | B3: =COUNTA('Pricing Data'!A2:A5001) -> 5000
A4: Total Exceptions | B4: =COUNTIF('Pricing Data'!M2:M5001,"<>PASS") -> 822
A5: Exception Rate | B5: =B4/B3 -> 0.1644
A6: High Priority Exceptions | B6: =COUNTIF('Pricing Data'!N2:N5001,"HIGH") -> 307
A7: Medium Priority Exceptions | B7: =COUNTIF('Pricing Data'!N2:N5001,"MEDIUM") -> 160
A8: Low Priority Exceptions | B8: =COUNTIF('Pricing Data'!N2:N5001,"LOW") -> 355
A9: Unclassified Exceptions | B9: =B4-SUM(B6:B8) -> 0
A12: Exception Type | B12: Count
A13: MISSING | B13: =COUNTIF('Pricing Data'!M2:M5001,"MISSING") -> 58
A14: STALE | B14: =COUNTIF('Pricing Data'!M2:M5001,"STALE") -> 467
A15: LARGE MOVE | B15: =COUNTIF('Pricing Data'!M2:M5001,"LARGE MOVE") -> 145
A16: VENDOR DIFFERENCE | B16: =COUNTIF('Pricing Data'!M2:M5001,"VENDOR DIFFERENCE") -> 152
A19: Key Insights
A20: • 822 of 5,000 securities were flagged for review, representing a 16.44% exception rate.
A21: • Stale prices were the largest exception category, with 467 cases.
A22: • 307 exceptions were classified as high priority, representing 37% of all exceptions.
